2025-03-28 17:43:48,799 INFO    MainThread:313412 [wandb_setup.py:_flush():67] Current SDK version is 0.19.8
2025-03-28 17:43:48,799 INFO    MainThread:313412 [wandb_setup.py:_flush():67] Configure stats pid to 313412
2025-03-28 17:43:48,800 INFO    MainThread:313412 [wandb_setup.py:_flush():67] Loading settings from /home/cxccxc/.config/wandb/settings
2025-03-28 17:43:48,800 INFO    MainThread:313412 [wandb_setup.py:_flush():67] Loading settings from /mnt/d/sandbox/yingSheWu/T3/wandb/settings
2025-03-28 17:43:48,800 INFO    MainThread:313412 [wandb_setup.py:_flush():67] Loading settings from environment variables
2025-03-28 17:43:48,800 INFO    MainThread:313412 [wandb_init.py:setup_run_log_directory():647] Logging user logs to /mnt/d/sandbox/yingSheWu/T3/wandb/run-20250328_174348-xmk3d0jw/logs/debug.log
2025-03-28 17:43:48,801 INFO    MainThread:313412 [wandb_init.py:setup_run_log_directory():648] Logging internal logs to /mnt/d/sandbox/yingSheWu/T3/wandb/run-20250328_174348-xmk3d0jw/logs/debug-internal.log
2025-03-28 17:43:48,801 INFO    MainThread:313412 [wandb_init.py:init():761] calling init triggers
2025-03-28 17:43:48,801 INFO    MainThread:313412 [wandb_init.py:init():766] wandb.init called with sweep_config: {}
config: {'board_size': 5, 'num_epochs': 10000, 'T_HORIZON': 200, 'gamma': 0.99, 'learning_rate': 0.0003, '_wandb': {}}
2025-03-28 17:43:48,802 INFO    MainThread:313412 [wandb_init.py:init():784] starting backend
2025-03-28 17:43:48,802 INFO    MainThread:313412 [wandb_init.py:init():788] sending inform_init request
2025-03-28 17:43:48,807 INFO    MainThread:313412 [backend.py:_multiprocessing_setup():101] multiprocessing start_methods=fork,spawn,forkserver, using: spawn
2025-03-28 17:43:48,807 INFO    MainThread:313412 [wandb_init.py:init():798] backend started and connected
2025-03-28 17:43:48,808 INFO    MainThread:313412 [wandb_init.py:init():891] updated telemetry
2025-03-28 17:43:48,863 INFO    MainThread:313412 [wandb_init.py:init():915] communicating run to backend with 90.0 second timeout
2025-03-28 17:43:49,985 INFO    MainThread:313412 [wandb_init.py:init():990] starting run threads in backend
2025-03-28 17:43:50,034 INFO    MainThread:313412 [wandb_run.py:_console_start():2375] atexit reg
2025-03-28 17:43:50,034 INFO    MainThread:313412 [wandb_run.py:_redirect():2227] redirect: wrap_raw
2025-03-28 17:43:50,034 INFO    MainThread:313412 [wandb_run.py:_redirect():2292] Wrapping output streams.
2025-03-28 17:43:50,034 INFO    MainThread:313412 [wandb_run.py:_redirect():2315] Redirects installed.
2025-03-28 17:43:50,036 INFO    MainThread:313412 [wandb_init.py:init():1032] run started, returning control to user process
2025-03-28 17:44:30,035 INFO    MsgRouterThr:313412 [mailbox.py:close():129] Closing mailbox, abandoning 1 handles.
2025-03-28 17:44:33,459 ERROR   MainThread:313412 [redirect.py:_on_write():661] error in stderr callback
Traceback (most recent call last):
  File "/home/cxccxc/anaconda3/envs/SDXL/lib/python3.10/site-packages/wandb/sdk/lib/redirect.py", line 659, in _on_write
    cb(written_data)
  File "/home/cxccxc/anaconda3/envs/SDXL/lib/python3.10/site-packages/wandb/sdk/wandb_run.py", line 2302, in <lambda>
    lambda data: self._console_raw_callback("stderr", data),
  File "/home/cxccxc/anaconda3/envs/SDXL/lib/python3.10/site-packages/wandb/sdk/wandb_run.py", line 401, in wrapper_fn
    return func(self, *args, **kwargs)
  File "/home/cxccxc/anaconda3/envs/SDXL/lib/python3.10/site-packages/wandb/sdk/wandb_run.py", line 1444, in _console_raw_callback
    self._backend.interface.publish_output_raw(name, data)
  File "/home/cxccxc/anaconda3/envs/SDXL/lib/python3.10/site-packages/wandb/sdk/interface/interface.py", line 761, in publish_output_raw
    self._publish_output_raw(o)
  File "/home/cxccxc/anaconda3/envs/SDXL/lib/python3.10/site-packages/wandb/sdk/interface/interface_shared.py", line 38, in _publish_output_raw
    self._publish(rec)
  File "/home/cxccxc/anaconda3/envs/SDXL/lib/python3.10/site-packages/wandb/sdk/interface/interface_sock.py", line 39, in _publish
    self._sock_client.send_record_publish(record)
  File "/home/cxccxc/anaconda3/envs/SDXL/lib/python3.10/site-packages/wandb/sdk/lib/sock_client.py", line 174, in send_record_publish
    self.send_server_request(server_req)
  File "/home/cxccxc/anaconda3/envs/SDXL/lib/python3.10/site-packages/wandb/sdk/lib/sock_client.py", line 154, in send_server_request
    self._send_message(msg)
  File "/home/cxccxc/anaconda3/envs/SDXL/lib/python3.10/site-packages/wandb/sdk/lib/sock_client.py", line 151, in _send_message
    self._sendall_with_error_handle(header + data)
  File "/home/cxccxc/anaconda3/envs/SDXL/lib/python3.10/site-packages/wandb/sdk/lib/sock_client.py", line 130, in _sendall_with_error_handle
    sent = self._sock.send(data)
BrokenPipeError: [Errno 32] Broken pipe
2025-03-28 17:44:33,462 ERROR   MainThread:313412 [redirect.py:_on_write():661] error in stderr callback
Traceback (most recent call last):
  File "/home/cxccxc/anaconda3/envs/SDXL/lib/python3.10/site-packages/wandb/sdk/lib/redirect.py", line 659, in _on_write
    cb(written_data)
  File "/home/cxccxc/anaconda3/envs/SDXL/lib/python3.10/site-packages/wandb/sdk/wandb_run.py", line 2302, in <lambda>
    lambda data: self._console_raw_callback("stderr", data),
  File "/home/cxccxc/anaconda3/envs/SDXL/lib/python3.10/site-packages/wandb/sdk/wandb_run.py", line 401, in wrapper_fn
    return func(self, *args, **kwargs)
  File "/home/cxccxc/anaconda3/envs/SDXL/lib/python3.10/site-packages/wandb/sdk/wandb_run.py", line 1444, in _console_raw_callback
    self._backend.interface.publish_output_raw(name, data)
  File "/home/cxccxc/anaconda3/envs/SDXL/lib/python3.10/site-packages/wandb/sdk/interface/interface.py", line 761, in publish_output_raw
    self._publish_output_raw(o)
  File "/home/cxccxc/anaconda3/envs/SDXL/lib/python3.10/site-packages/wandb/sdk/interface/interface_shared.py", line 38, in _publish_output_raw
    self._publish(rec)
  File "/home/cxccxc/anaconda3/envs/SDXL/lib/python3.10/site-packages/wandb/sdk/interface/interface_sock.py", line 39, in _publish
    self._sock_client.send_record_publish(record)
  File "/home/cxccxc/anaconda3/envs/SDXL/lib/python3.10/site-packages/wandb/sdk/lib/sock_client.py", line 174, in send_record_publish
    self.send_server_request(server_req)
  File "/home/cxccxc/anaconda3/envs/SDXL/lib/python3.10/site-packages/wandb/sdk/lib/sock_client.py", line 154, in send_server_request
    self._send_message(msg)
  File "/home/cxccxc/anaconda3/envs/SDXL/lib/python3.10/site-packages/wandb/sdk/lib/sock_client.py", line 151, in _send_message
    self._sendall_with_error_handle(header + data)
  File "/home/cxccxc/anaconda3/envs/SDXL/lib/python3.10/site-packages/wandb/sdk/lib/sock_client.py", line 130, in _sendall_with_error_handle
    sent = self._sock.send(data)
BrokenPipeError: [Errno 32] Broken pipe
2025-03-28 17:44:33,463 ERROR   MainThread:313412 [redirect.py:_on_write():661] error in stderr callback
Traceback (most recent call last):
  File "/home/cxccxc/anaconda3/envs/SDXL/lib/python3.10/site-packages/wandb/sdk/lib/redirect.py", line 659, in _on_write
    cb(written_data)
  File "/home/cxccxc/anaconda3/envs/SDXL/lib/python3.10/site-packages/wandb/sdk/wandb_run.py", line 2302, in <lambda>
    lambda data: self._console_raw_callback("stderr", data),
  File "/home/cxccxc/anaconda3/envs/SDXL/lib/python3.10/site-packages/wandb/sdk/wandb_run.py", line 401, in wrapper_fn
    return func(self, *args, **kwargs)
  File "/home/cxccxc/anaconda3/envs/SDXL/lib/python3.10/site-packages/wandb/sdk/wandb_run.py", line 1444, in _console_raw_callback
    self._backend.interface.publish_output_raw(name, data)
  File "/home/cxccxc/anaconda3/envs/SDXL/lib/python3.10/site-packages/wandb/sdk/interface/interface.py", line 761, in publish_output_raw
    self._publish_output_raw(o)
  File "/home/cxccxc/anaconda3/envs/SDXL/lib/python3.10/site-packages/wandb/sdk/interface/interface_shared.py", line 38, in _publish_output_raw
    self._publish(rec)
  File "/home/cxccxc/anaconda3/envs/SDXL/lib/python3.10/site-packages/wandb/sdk/interface/interface_sock.py", line 39, in _publish
    self._sock_client.send_record_publish(record)
  File "/home/cxccxc/anaconda3/envs/SDXL/lib/python3.10/site-packages/wandb/sdk/lib/sock_client.py", line 174, in send_record_publish
    self.send_server_request(server_req)
  File "/home/cxccxc/anaconda3/envs/SDXL/lib/python3.10/site-packages/wandb/sdk/lib/sock_client.py", line 154, in send_server_request
    self._send_message(msg)
  File "/home/cxccxc/anaconda3/envs/SDXL/lib/python3.10/site-packages/wandb/sdk/lib/sock_client.py", line 151, in _send_message
    self._sendall_with_error_handle(header + data)
  File "/home/cxccxc/anaconda3/envs/SDXL/lib/python3.10/site-packages/wandb/sdk/lib/sock_client.py", line 130, in _sendall_with_error_handle
    sent = self._sock.send(data)
BrokenPipeError: [Errno 32] Broken pipe
2025-03-28 17:44:33,463 ERROR   MainThread:313412 [redirect.py:_on_write():661] error in stderr callback
Traceback (most recent call last):
  File "/home/cxccxc/anaconda3/envs/SDXL/lib/python3.10/site-packages/wandb/sdk/lib/redirect.py", line 659, in _on_write
    cb(written_data)
  File "/home/cxccxc/anaconda3/envs/SDXL/lib/python3.10/site-packages/wandb/sdk/wandb_run.py", line 2302, in <lambda>
    lambda data: self._console_raw_callback("stderr", data),
  File "/home/cxccxc/anaconda3/envs/SDXL/lib/python3.10/site-packages/wandb/sdk/wandb_run.py", line 401, in wrapper_fn
    return func(self, *args, **kwargs)
  File "/home/cxccxc/anaconda3/envs/SDXL/lib/python3.10/site-packages/wandb/sdk/wandb_run.py", line 1444, in _console_raw_callback
    self._backend.interface.publish_output_raw(name, data)
  File "/home/cxccxc/anaconda3/envs/SDXL/lib/python3.10/site-packages/wandb/sdk/interface/interface.py", line 761, in publish_output_raw
    self._publish_output_raw(o)
  File "/home/cxccxc/anaconda3/envs/SDXL/lib/python3.10/site-packages/wandb/sdk/interface/interface_shared.py", line 38, in _publish_output_raw
    self._publish(rec)
  File "/home/cxccxc/anaconda3/envs/SDXL/lib/python3.10/site-packages/wandb/sdk/interface/interface_sock.py", line 39, in _publish
    self._sock_client.send_record_publish(record)
  File "/home/cxccxc/anaconda3/envs/SDXL/lib/python3.10/site-packages/wandb/sdk/lib/sock_client.py", line 174, in send_record_publish
    self.send_server_request(server_req)
  File "/home/cxccxc/anaconda3/envs/SDXL/lib/python3.10/site-packages/wandb/sdk/lib/sock_client.py", line 154, in send_server_request
    self._send_message(msg)
  File "/home/cxccxc/anaconda3/envs/SDXL/lib/python3.10/site-packages/wandb/sdk/lib/sock_client.py", line 151, in _send_message
    self._sendall_with_error_handle(header + data)
  File "/home/cxccxc/anaconda3/envs/SDXL/lib/python3.10/site-packages/wandb/sdk/lib/sock_client.py", line 130, in _sendall_with_error_handle
    sent = self._sock.send(data)
BrokenPipeError: [Errno 32] Broken pipe
2025-03-28 17:44:33,463 ERROR   MainThread:313412 [redirect.py:_on_write():661] error in stderr callback
Traceback (most recent call last):
  File "/home/cxccxc/anaconda3/envs/SDXL/lib/python3.10/site-packages/wandb/sdk/lib/redirect.py", line 659, in _on_write
    cb(written_data)
  File "/home/cxccxc/anaconda3/envs/SDXL/lib/python3.10/site-packages/wandb/sdk/wandb_run.py", line 2302, in <lambda>
    lambda data: self._console_raw_callback("stderr", data),
  File "/home/cxccxc/anaconda3/envs/SDXL/lib/python3.10/site-packages/wandb/sdk/wandb_run.py", line 401, in wrapper_fn
    return func(self, *args, **kwargs)
  File "/home/cxccxc/anaconda3/envs/SDXL/lib/python3.10/site-packages/wandb/sdk/wandb_run.py", line 1444, in _console_raw_callback
    self._backend.interface.publish_output_raw(name, data)
  File "/home/cxccxc/anaconda3/envs/SDXL/lib/python3.10/site-packages/wandb/sdk/interface/interface.py", line 761, in publish_output_raw
    self._publish_output_raw(o)
  File "/home/cxccxc/anaconda3/envs/SDXL/lib/python3.10/site-packages/wandb/sdk/interface/interface_shared.py", line 38, in _publish_output_raw
    self._publish(rec)
  File "/home/cxccxc/anaconda3/envs/SDXL/lib/python3.10/site-packages/wandb/sdk/interface/interface_sock.py", line 39, in _publish
    self._sock_client.send_record_publish(record)
  File "/home/cxccxc/anaconda3/envs/SDXL/lib/python3.10/site-packages/wandb/sdk/lib/sock_client.py", line 174, in send_record_publish
    self.send_server_request(server_req)
  File "/home/cxccxc/anaconda3/envs/SDXL/lib/python3.10/site-packages/wandb/sdk/lib/sock_client.py", line 154, in send_server_request
    self._send_message(msg)
  File "/home/cxccxc/anaconda3/envs/SDXL/lib/python3.10/site-packages/wandb/sdk/lib/sock_client.py", line 151, in _send_message
    self._sendall_with_error_handle(header + data)
  File "/home/cxccxc/anaconda3/envs/SDXL/lib/python3.10/site-packages/wandb/sdk/lib/sock_client.py", line 130, in _sendall_with_error_handle
    sent = self._sock.send(data)
BrokenPipeError: [Errno 32] Broken pipe
2025-03-28 17:44:33,463 ERROR   MainThread:313412 [redirect.py:_on_write():661] error in stderr callback
Traceback (most recent call last):
  File "/home/cxccxc/anaconda3/envs/SDXL/lib/python3.10/site-packages/wandb/sdk/lib/redirect.py", line 659, in _on_write
    cb(written_data)
  File "/home/cxccxc/anaconda3/envs/SDXL/lib/python3.10/site-packages/wandb/sdk/wandb_run.py", line 2302, in <lambda>
    lambda data: self._console_raw_callback("stderr", data),
  File "/home/cxccxc/anaconda3/envs/SDXL/lib/python3.10/site-packages/wandb/sdk/wandb_run.py", line 401, in wrapper_fn
    return func(self, *args, **kwargs)
  File "/home/cxccxc/anaconda3/envs/SDXL/lib/python3.10/site-packages/wandb/sdk/wandb_run.py", line 1444, in _console_raw_callback
    self._backend.interface.publish_output_raw(name, data)
  File "/home/cxccxc/anaconda3/envs/SDXL/lib/python3.10/site-packages/wandb/sdk/interface/interface.py", line 761, in publish_output_raw
    self._publish_output_raw(o)
  File "/home/cxccxc/anaconda3/envs/SDXL/lib/python3.10/site-packages/wandb/sdk/interface/interface_shared.py", line 38, in _publish_output_raw
    self._publish(rec)
  File "/home/cxccxc/anaconda3/envs/SDXL/lib/python3.10/site-packages/wandb/sdk/interface/interface_sock.py", line 39, in _publish
    self._sock_client.send_record_publish(record)
  File "/home/cxccxc/anaconda3/envs/SDXL/lib/python3.10/site-packages/wandb/sdk/lib/sock_client.py", line 174, in send_record_publish
    self.send_server_request(server_req)
  File "/home/cxccxc/anaconda3/envs/SDXL/lib/python3.10/site-packages/wandb/sdk/lib/sock_client.py", line 154, in send_server_request
    self._send_message(msg)
  File "/home/cxccxc/anaconda3/envs/SDXL/lib/python3.10/site-packages/wandb/sdk/lib/sock_client.py", line 151, in _send_message
    self._sendall_with_error_handle(header + data)
  File "/home/cxccxc/anaconda3/envs/SDXL/lib/python3.10/site-packages/wandb/sdk/lib/sock_client.py", line 130, in _sendall_with_error_handle
    sent = self._sock.send(data)
BrokenPipeError: [Errno 32] Broken pipe
2025-03-28 17:44:33,464 ERROR   MainThread:313412 [redirect.py:_on_write():661] error in stderr callback
Traceback (most recent call last):
  File "/home/cxccxc/anaconda3/envs/SDXL/lib/python3.10/site-packages/wandb/sdk/lib/redirect.py", line 659, in _on_write
    cb(written_data)
  File "/home/cxccxc/anaconda3/envs/SDXL/lib/python3.10/site-packages/wandb/sdk/wandb_run.py", line 2302, in <lambda>
    lambda data: self._console_raw_callback("stderr", data),
  File "/home/cxccxc/anaconda3/envs/SDXL/lib/python3.10/site-packages/wandb/sdk/wandb_run.py", line 401, in wrapper_fn
    return func(self, *args, **kwargs)
  File "/home/cxccxc/anaconda3/envs/SDXL/lib/python3.10/site-packages/wandb/sdk/wandb_run.py", line 1444, in _console_raw_callback
    self._backend.interface.publish_output_raw(name, data)
  File "/home/cxccxc/anaconda3/envs/SDXL/lib/python3.10/site-packages/wandb/sdk/interface/interface.py", line 761, in publish_output_raw
    self._publish_output_raw(o)
  File "/home/cxccxc/anaconda3/envs/SDXL/lib/python3.10/site-packages/wandb/sdk/interface/interface_shared.py", line 38, in _publish_output_raw
    self._publish(rec)
  File "/home/cxccxc/anaconda3/envs/SDXL/lib/python3.10/site-packages/wandb/sdk/interface/interface_sock.py", line 39, in _publish
    self._sock_client.send_record_publish(record)
  File "/home/cxccxc/anaconda3/envs/SDXL/lib/python3.10/site-packages/wandb/sdk/lib/sock_client.py", line 174, in send_record_publish
    self.send_server_request(server_req)
  File "/home/cxccxc/anaconda3/envs/SDXL/lib/python3.10/site-packages/wandb/sdk/lib/sock_client.py", line 154, in send_server_request
    self._send_message(msg)
  File "/home/cxccxc/anaconda3/envs/SDXL/lib/python3.10/site-packages/wandb/sdk/lib/sock_client.py", line 151, in _send_message
    self._sendall_with_error_handle(header + data)
  File "/home/cxccxc/anaconda3/envs/SDXL/lib/python3.10/site-packages/wandb/sdk/lib/sock_client.py", line 130, in _sendall_with_error_handle
    sent = self._sock.send(data)
BrokenPipeError: [Errno 32] Broken pipe
2025-03-28 17:44:33,465 ERROR   MainThread:313412 [redirect.py:_on_write():661] error in stderr callback
Traceback (most recent call last):
  File "/home/cxccxc/anaconda3/envs/SDXL/lib/python3.10/site-packages/wandb/sdk/lib/redirect.py", line 659, in _on_write
    cb(written_data)
  File "/home/cxccxc/anaconda3/envs/SDXL/lib/python3.10/site-packages/wandb/sdk/wandb_run.py", line 2302, in <lambda>
    lambda data: self._console_raw_callback("stderr", data),
  File "/home/cxccxc/anaconda3/envs/SDXL/lib/python3.10/site-packages/wandb/sdk/wandb_run.py", line 401, in wrapper_fn
    return func(self, *args, **kwargs)
  File "/home/cxccxc/anaconda3/envs/SDXL/lib/python3.10/site-packages/wandb/sdk/wandb_run.py", line 1444, in _console_raw_callback
    self._backend.interface.publish_output_raw(name, data)
  File "/home/cxccxc/anaconda3/envs/SDXL/lib/python3.10/site-packages/wandb/sdk/interface/interface.py", line 761, in publish_output_raw
    self._publish_output_raw(o)
  File "/home/cxccxc/anaconda3/envs/SDXL/lib/python3.10/site-packages/wandb/sdk/interface/interface_shared.py", line 38, in _publish_output_raw
    self._publish(rec)
  File "/home/cxccxc/anaconda3/envs/SDXL/lib/python3.10/site-packages/wandb/sdk/interface/interface_sock.py", line 39, in _publish
    self._sock_client.send_record_publish(record)
  File "/home/cxccxc/anaconda3/envs/SDXL/lib/python3.10/site-packages/wandb/sdk/lib/sock_client.py", line 174, in send_record_publish
    self.send_server_request(server_req)
  File "/home/cxccxc/anaconda3/envs/SDXL/lib/python3.10/site-packages/wandb/sdk/lib/sock_client.py", line 154, in send_server_request
    self._send_message(msg)
  File "/home/cxccxc/anaconda3/envs/SDXL/lib/python3.10/site-packages/wandb/sdk/lib/sock_client.py", line 151, in _send_message
    self._sendall_with_error_handle(header + data)
  File "/home/cxccxc/anaconda3/envs/SDXL/lib/python3.10/site-packages/wandb/sdk/lib/sock_client.py", line 130, in _sendall_with_error_handle
    sent = self._sock.send(data)
BrokenPipeError: [Errno 32] Broken pipe
2025-03-28 17:44:33,466 ERROR   MainThread:313412 [redirect.py:_on_write():661] error in stderr callback
Traceback (most recent call last):
  File "/home/cxccxc/anaconda3/envs/SDXL/lib/python3.10/site-packages/wandb/sdk/lib/redirect.py", line 659, in _on_write
    cb(written_data)
  File "/home/cxccxc/anaconda3/envs/SDXL/lib/python3.10/site-packages/wandb/sdk/wandb_run.py", line 2302, in <lambda>
    lambda data: self._console_raw_callback("stderr", data),
  File "/home/cxccxc/anaconda3/envs/SDXL/lib/python3.10/site-packages/wandb/sdk/wandb_run.py", line 401, in wrapper_fn
    return func(self, *args, **kwargs)
  File "/home/cxccxc/anaconda3/envs/SDXL/lib/python3.10/site-packages/wandb/sdk/wandb_run.py", line 1444, in _console_raw_callback
    self._backend.interface.publish_output_raw(name, data)
  File "/home/cxccxc/anaconda3/envs/SDXL/lib/python3.10/site-packages/wandb/sdk/interface/interface.py", line 761, in publish_output_raw
    self._publish_output_raw(o)
  File "/home/cxccxc/anaconda3/envs/SDXL/lib/python3.10/site-packages/wandb/sdk/interface/interface_shared.py", line 38, in _publish_output_raw
    self._publish(rec)
  File "/home/cxccxc/anaconda3/envs/SDXL/lib/python3.10/site-packages/wandb/sdk/interface/interface_sock.py", line 39, in _publish
    self._sock_client.send_record_publish(record)
  File "/home/cxccxc/anaconda3/envs/SDXL/lib/python3.10/site-packages/wandb/sdk/lib/sock_client.py", line 174, in send_record_publish
    self.send_server_request(server_req)
  File "/home/cxccxc/anaconda3/envs/SDXL/lib/python3.10/site-packages/wandb/sdk/lib/sock_client.py", line 154, in send_server_request
    self._send_message(msg)
  File "/home/cxccxc/anaconda3/envs/SDXL/lib/python3.10/site-packages/wandb/sdk/lib/sock_client.py", line 151, in _send_message
    self._sendall_with_error_handle(header + data)
  File "/home/cxccxc/anaconda3/envs/SDXL/lib/python3.10/site-packages/wandb/sdk/lib/sock_client.py", line 130, in _sendall_with_error_handle
    sent = self._sock.send(data)
BrokenPipeError: [Errno 32] Broken pipe
2025-03-28 17:44:33,466 ERROR   MainThread:313412 [redirect.py:_on_write():661] error in stderr callback
Traceback (most recent call last):
  File "/home/cxccxc/anaconda3/envs/SDXL/lib/python3.10/site-packages/wandb/sdk/lib/redirect.py", line 659, in _on_write
    cb(written_data)
  File "/home/cxccxc/anaconda3/envs/SDXL/lib/python3.10/site-packages/wandb/sdk/wandb_run.py", line 2302, in <lambda>
    lambda data: self._console_raw_callback("stderr", data),
  File "/home/cxccxc/anaconda3/envs/SDXL/lib/python3.10/site-packages/wandb/sdk/wandb_run.py", line 401, in wrapper_fn
    return func(self, *args, **kwargs)
  File "/home/cxccxc/anaconda3/envs/SDXL/lib/python3.10/site-packages/wandb/sdk/wandb_run.py", line 1444, in _console_raw_callback
    self._backend.interface.publish_output_raw(name, data)
  File "/home/cxccxc/anaconda3/envs/SDXL/lib/python3.10/site-packages/wandb/sdk/interface/interface.py", line 761, in publish_output_raw
    self._publish_output_raw(o)
  File "/home/cxccxc/anaconda3/envs/SDXL/lib/python3.10/site-packages/wandb/sdk/interface/interface_shared.py", line 38, in _publish_output_raw
    self._publish(rec)
  File "/home/cxccxc/anaconda3/envs/SDXL/lib/python3.10/site-packages/wandb/sdk/interface/interface_sock.py", line 39, in _publish
    self._sock_client.send_record_publish(record)
  File "/home/cxccxc/anaconda3/envs/SDXL/lib/python3.10/site-packages/wandb/sdk/lib/sock_client.py", line 174, in send_record_publish
    self.send_server_request(server_req)
  File "/home/cxccxc/anaconda3/envs/SDXL/lib/python3.10/site-packages/wandb/sdk/lib/sock_client.py", line 154, in send_server_request
    self._send_message(msg)
  File "/home/cxccxc/anaconda3/envs/SDXL/lib/python3.10/site-packages/wandb/sdk/lib/sock_client.py", line 151, in _send_message
    self._sendall_with_error_handle(header + data)
  File "/home/cxccxc/anaconda3/envs/SDXL/lib/python3.10/site-packages/wandb/sdk/lib/sock_client.py", line 130, in _sendall_with_error_handle
    sent = self._sock.send(data)
BrokenPipeError: [Errno 32] Broken pipe
2025-03-28 17:44:33,466 ERROR   MainThread:313412 [redirect.py:_on_write():661] error in stderr callback
Traceback (most recent call last):
  File "/home/cxccxc/anaconda3/envs/SDXL/lib/python3.10/site-packages/wandb/sdk/lib/redirect.py", line 659, in _on_write
    cb(written_data)
  File "/home/cxccxc/anaconda3/envs/SDXL/lib/python3.10/site-packages/wandb/sdk/wandb_run.py", line 2302, in <lambda>
    lambda data: self._console_raw_callback("stderr", data),
  File "/home/cxccxc/anaconda3/envs/SDXL/lib/python3.10/site-packages/wandb/sdk/wandb_run.py", line 401, in wrapper_fn
    return func(self, *args, **kwargs)
  File "/home/cxccxc/anaconda3/envs/SDXL/lib/python3.10/site-packages/wandb/sdk/wandb_run.py", line 1444, in _console_raw_callback
    self._backend.interface.publish_output_raw(name, data)
  File "/home/cxccxc/anaconda3/envs/SDXL/lib/python3.10/site-packages/wandb/sdk/interface/interface.py", line 761, in publish_output_raw
    self._publish_output_raw(o)
  File "/home/cxccxc/anaconda3/envs/SDXL/lib/python3.10/site-packages/wandb/sdk/interface/interface_shared.py", line 38, in _publish_output_raw
    self._publish(rec)
  File "/home/cxccxc/anaconda3/envs/SDXL/lib/python3.10/site-packages/wandb/sdk/interface/interface_sock.py", line 39, in _publish
    self._sock_client.send_record_publish(record)
  File "/home/cxccxc/anaconda3/envs/SDXL/lib/python3.10/site-packages/wandb/sdk/lib/sock_client.py", line 174, in send_record_publish
    self.send_server_request(server_req)
  File "/home/cxccxc/anaconda3/envs/SDXL/lib/python3.10/site-packages/wandb/sdk/lib/sock_client.py", line 154, in send_server_request
    self._send_message(msg)
  File "/home/cxccxc/anaconda3/envs/SDXL/lib/python3.10/site-packages/wandb/sdk/lib/sock_client.py", line 151, in _send_message
    self._sendall_with_error_handle(header + data)
  File "/home/cxccxc/anaconda3/envs/SDXL/lib/python3.10/site-packages/wandb/sdk/lib/sock_client.py", line 130, in _sendall_with_error_handle
    sent = self._sock.send(data)
BrokenPipeError: [Errno 32] Broken pipe
2025-03-28 17:44:33,466 ERROR   MainThread:313412 [redirect.py:_on_write():661] error in stderr callback
Traceback (most recent call last):
  File "/home/cxccxc/anaconda3/envs/SDXL/lib/python3.10/site-packages/wandb/sdk/lib/redirect.py", line 659, in _on_write
    cb(written_data)
  File "/home/cxccxc/anaconda3/envs/SDXL/lib/python3.10/site-packages/wandb/sdk/wandb_run.py", line 2302, in <lambda>
    lambda data: self._console_raw_callback("stderr", data),
  File "/home/cxccxc/anaconda3/envs/SDXL/lib/python3.10/site-packages/wandb/sdk/wandb_run.py", line 401, in wrapper_fn
    return func(self, *args, **kwargs)
  File "/home/cxccxc/anaconda3/envs/SDXL/lib/python3.10/site-packages/wandb/sdk/wandb_run.py", line 1444, in _console_raw_callback
    self._backend.interface.publish_output_raw(name, data)
  File "/home/cxccxc/anaconda3/envs/SDXL/lib/python3.10/site-packages/wandb/sdk/interface/interface.py", line 761, in publish_output_raw
    self._publish_output_raw(o)
  File "/home/cxccxc/anaconda3/envs/SDXL/lib/python3.10/site-packages/wandb/sdk/interface/interface_shared.py", line 38, in _publish_output_raw
    self._publish(rec)
  File "/home/cxccxc/anaconda3/envs/SDXL/lib/python3.10/site-packages/wandb/sdk/interface/interface_sock.py", line 39, in _publish
    self._sock_client.send_record_publish(record)
  File "/home/cxccxc/anaconda3/envs/SDXL/lib/python3.10/site-packages/wandb/sdk/lib/sock_client.py", line 174, in send_record_publish
    self.send_server_request(server_req)
  File "/home/cxccxc/anaconda3/envs/SDXL/lib/python3.10/site-packages/wandb/sdk/lib/sock_client.py", line 154, in send_server_request
    self._send_message(msg)
  File "/home/cxccxc/anaconda3/envs/SDXL/lib/python3.10/site-packages/wandb/sdk/lib/sock_client.py", line 151, in _send_message
    self._sendall_with_error_handle(header + data)
  File "/home/cxccxc/anaconda3/envs/SDXL/lib/python3.10/site-packages/wandb/sdk/lib/sock_client.py", line 130, in _sendall_with_error_handle
    sent = self._sock.send(data)
BrokenPipeError: [Errno 32] Broken pipe
2025-03-28 17:44:33,467 ERROR   MainThread:313412 [redirect.py:_on_write():661] error in stderr callback
Traceback (most recent call last):
  File "/home/cxccxc/anaconda3/envs/SDXL/lib/python3.10/site-packages/wandb/sdk/lib/redirect.py", line 659, in _on_write
    cb(written_data)
  File "/home/cxccxc/anaconda3/envs/SDXL/lib/python3.10/site-packages/wandb/sdk/wandb_run.py", line 2302, in <lambda>
    lambda data: self._console_raw_callback("stderr", data),
  File "/home/cxccxc/anaconda3/envs/SDXL/lib/python3.10/site-packages/wandb/sdk/wandb_run.py", line 401, in wrapper_fn
    return func(self, *args, **kwargs)
  File "/home/cxccxc/anaconda3/envs/SDXL/lib/python3.10/site-packages/wandb/sdk/wandb_run.py", line 1444, in _console_raw_callback
    self._backend.interface.publish_output_raw(name, data)
  File "/home/cxccxc/anaconda3/envs/SDXL/lib/python3.10/site-packages/wandb/sdk/interface/interface.py", line 761, in publish_output_raw
    self._publish_output_raw(o)
  File "/home/cxccxc/anaconda3/envs/SDXL/lib/python3.10/site-packages/wandb/sdk/interface/interface_shared.py", line 38, in _publish_output_raw
    self._publish(rec)
  File "/home/cxccxc/anaconda3/envs/SDXL/lib/python3.10/site-packages/wandb/sdk/interface/interface_sock.py", line 39, in _publish
    self._sock_client.send_record_publish(record)
  File "/home/cxccxc/anaconda3/envs/SDXL/lib/python3.10/site-packages/wandb/sdk/lib/sock_client.py", line 174, in send_record_publish
    self.send_server_request(server_req)
  File "/home/cxccxc/anaconda3/envs/SDXL/lib/python3.10/site-packages/wandb/sdk/lib/sock_client.py", line 154, in send_server_request
    self._send_message(msg)
  File "/home/cxccxc/anaconda3/envs/SDXL/lib/python3.10/site-packages/wandb/sdk/lib/sock_client.py", line 151, in _send_message
    self._sendall_with_error_handle(header + data)
  File "/home/cxccxc/anaconda3/envs/SDXL/lib/python3.10/site-packages/wandb/sdk/lib/sock_client.py", line 130, in _sendall_with_error_handle
    sent = self._sock.send(data)
BrokenPipeError: [Errno 32] Broken pipe
2025-03-28 17:44:33,467 ERROR   MainThread:313412 [redirect.py:_on_write():661] error in stderr callback
Traceback (most recent call last):
  File "/home/cxccxc/anaconda3/envs/SDXL/lib/python3.10/site-packages/wandb/sdk/lib/redirect.py", line 659, in _on_write
    cb(written_data)
  File "/home/cxccxc/anaconda3/envs/SDXL/lib/python3.10/site-packages/wandb/sdk/wandb_run.py", line 2302, in <lambda>
    lambda data: self._console_raw_callback("stderr", data),
  File "/home/cxccxc/anaconda3/envs/SDXL/lib/python3.10/site-packages/wandb/sdk/wandb_run.py", line 401, in wrapper_fn
    return func(self, *args, **kwargs)
  File "/home/cxccxc/anaconda3/envs/SDXL/lib/python3.10/site-packages/wandb/sdk/wandb_run.py", line 1444, in _console_raw_callback
    self._backend.interface.publish_output_raw(name, data)
  File "/home/cxccxc/anaconda3/envs/SDXL/lib/python3.10/site-packages/wandb/sdk/interface/interface.py", line 761, in publish_output_raw
    self._publish_output_raw(o)
  File "/home/cxccxc/anaconda3/envs/SDXL/lib/python3.10/site-packages/wandb/sdk/interface/interface_shared.py", line 38, in _publish_output_raw
    self._publish(rec)
  File "/home/cxccxc/anaconda3/envs/SDXL/lib/python3.10/site-packages/wandb/sdk/interface/interface_sock.py", line 39, in _publish
    self._sock_client.send_record_publish(record)
  File "/home/cxccxc/anaconda3/envs/SDXL/lib/python3.10/site-packages/wandb/sdk/lib/sock_client.py", line 174, in send_record_publish
    self.send_server_request(server_req)
  File "/home/cxccxc/anaconda3/envs/SDXL/lib/python3.10/site-packages/wandb/sdk/lib/sock_client.py", line 154, in send_server_request
    self._send_message(msg)
  File "/home/cxccxc/anaconda3/envs/SDXL/lib/python3.10/site-packages/wandb/sdk/lib/sock_client.py", line 151, in _send_message
    self._sendall_with_error_handle(header + data)
  File "/home/cxccxc/anaconda3/envs/SDXL/lib/python3.10/site-packages/wandb/sdk/lib/sock_client.py", line 130, in _sendall_with_error_handle
    sent = self._sock.send(data)
BrokenPipeError: [Errno 32] Broken pipe
2025-03-28 17:44:33,468 ERROR   MainThread:313412 [redirect.py:_on_write():661] error in stderr callback
Traceback (most recent call last):
  File "/home/cxccxc/anaconda3/envs/SDXL/lib/python3.10/site-packages/wandb/sdk/lib/redirect.py", line 659, in _on_write
    cb(written_data)
  File "/home/cxccxc/anaconda3/envs/SDXL/lib/python3.10/site-packages/wandb/sdk/wandb_run.py", line 2302, in <lambda>
    lambda data: self._console_raw_callback("stderr", data),
  File "/home/cxccxc/anaconda3/envs/SDXL/lib/python3.10/site-packages/wandb/sdk/wandb_run.py", line 401, in wrapper_fn
    return func(self, *args, **kwargs)
  File "/home/cxccxc/anaconda3/envs/SDXL/lib/python3.10/site-packages/wandb/sdk/wandb_run.py", line 1444, in _console_raw_callback
    self._backend.interface.publish_output_raw(name, data)
  File "/home/cxccxc/anaconda3/envs/SDXL/lib/python3.10/site-packages/wandb/sdk/interface/interface.py", line 761, in publish_output_raw
    self._publish_output_raw(o)
  File "/home/cxccxc/anaconda3/envs/SDXL/lib/python3.10/site-packages/wandb/sdk/interface/interface_shared.py", line 38, in _publish_output_raw
    self._publish(rec)
  File "/home/cxccxc/anaconda3/envs/SDXL/lib/python3.10/site-packages/wandb/sdk/interface/interface_sock.py", line 39, in _publish
    self._sock_client.send_record_publish(record)
  File "/home/cxccxc/anaconda3/envs/SDXL/lib/python3.10/site-packages/wandb/sdk/lib/sock_client.py", line 174, in send_record_publish
    self.send_server_request(server_req)
  File "/home/cxccxc/anaconda3/envs/SDXL/lib/python3.10/site-packages/wandb/sdk/lib/sock_client.py", line 154, in send_server_request
    self._send_message(msg)
  File "/home/cxccxc/anaconda3/envs/SDXL/lib/python3.10/site-packages/wandb/sdk/lib/sock_client.py", line 151, in _send_message
    self._sendall_with_error_handle(header + data)
  File "/home/cxccxc/anaconda3/envs/SDXL/lib/python3.10/site-packages/wandb/sdk/lib/sock_client.py", line 130, in _sendall_with_error_handle
    sent = self._sock.send(data)
BrokenPipeError: [Errno 32] Broken pipe
2025-03-28 17:44:33,468 ERROR   MainThread:313412 [redirect.py:_on_write():661] error in stderr callback
Traceback (most recent call last):
  File "/home/cxccxc/anaconda3/envs/SDXL/lib/python3.10/site-packages/wandb/sdk/lib/redirect.py", line 659, in _on_write
    cb(written_data)
  File "/home/cxccxc/anaconda3/envs/SDXL/lib/python3.10/site-packages/wandb/sdk/wandb_run.py", line 2302, in <lambda>
    lambda data: self._console_raw_callback("stderr", data),
  File "/home/cxccxc/anaconda3/envs/SDXL/lib/python3.10/site-packages/wandb/sdk/wandb_run.py", line 401, in wrapper_fn
    return func(self, *args, **kwargs)
  File "/home/cxccxc/anaconda3/envs/SDXL/lib/python3.10/site-packages/wandb/sdk/wandb_run.py", line 1444, in _console_raw_callback
    self._backend.interface.publish_output_raw(name, data)
  File "/home/cxccxc/anaconda3/envs/SDXL/lib/python3.10/site-packages/wandb/sdk/interface/interface.py", line 761, in publish_output_raw
    self._publish_output_raw(o)
  File "/home/cxccxc/anaconda3/envs/SDXL/lib/python3.10/site-packages/wandb/sdk/interface/interface_shared.py", line 38, in _publish_output_raw
    self._publish(rec)
  File "/home/cxccxc/anaconda3/envs/SDXL/lib/python3.10/site-packages/wandb/sdk/interface/interface_sock.py", line 39, in _publish
    self._sock_client.send_record_publish(record)
  File "/home/cxccxc/anaconda3/envs/SDXL/lib/python3.10/site-packages/wandb/sdk/lib/sock_client.py", line 174, in send_record_publish
    self.send_server_request(server_req)
  File "/home/cxccxc/anaconda3/envs/SDXL/lib/python3.10/site-packages/wandb/sdk/lib/sock_client.py", line 154, in send_server_request
    self._send_message(msg)
  File "/home/cxccxc/anaconda3/envs/SDXL/lib/python3.10/site-packages/wandb/sdk/lib/sock_client.py", line 151, in _send_message
    self._sendall_with_error_handle(header + data)
  File "/home/cxccxc/anaconda3/envs/SDXL/lib/python3.10/site-packages/wandb/sdk/lib/sock_client.py", line 130, in _sendall_with_error_handle
    sent = self._sock.send(data)
BrokenPipeError: [Errno 32] Broken pipe
2025-03-28 17:44:33,469 ERROR   MainThread:313412 [redirect.py:_on_write():661] error in stderr callback
Traceback (most recent call last):
  File "/home/cxccxc/anaconda3/envs/SDXL/lib/python3.10/site-packages/wandb/sdk/lib/redirect.py", line 659, in _on_write
    cb(written_data)
  File "/home/cxccxc/anaconda3/envs/SDXL/lib/python3.10/site-packages/wandb/sdk/wandb_run.py", line 2302, in <lambda>
    lambda data: self._console_raw_callback("stderr", data),
  File "/home/cxccxc/anaconda3/envs/SDXL/lib/python3.10/site-packages/wandb/sdk/wandb_run.py", line 401, in wrapper_fn
    return func(self, *args, **kwargs)
  File "/home/cxccxc/anaconda3/envs/SDXL/lib/python3.10/site-packages/wandb/sdk/wandb_run.py", line 1444, in _console_raw_callback
    self._backend.interface.publish_output_raw(name, data)
  File "/home/cxccxc/anaconda3/envs/SDXL/lib/python3.10/site-packages/wandb/sdk/interface/interface.py", line 761, in publish_output_raw
    self._publish_output_raw(o)
  File "/home/cxccxc/anaconda3/envs/SDXL/lib/python3.10/site-packages/wandb/sdk/interface/interface_shared.py", line 38, in _publish_output_raw
    self._publish(rec)
  File "/home/cxccxc/anaconda3/envs/SDXL/lib/python3.10/site-packages/wandb/sdk/interface/interface_sock.py", line 39, in _publish
    self._sock_client.send_record_publish(record)
  File "/home/cxccxc/anaconda3/envs/SDXL/lib/python3.10/site-packages/wandb/sdk/lib/sock_client.py", line 174, in send_record_publish
    self.send_server_request(server_req)
  File "/home/cxccxc/anaconda3/envs/SDXL/lib/python3.10/site-packages/wandb/sdk/lib/sock_client.py", line 154, in send_server_request
    self._send_message(msg)
  File "/home/cxccxc/anaconda3/envs/SDXL/lib/python3.10/site-packages/wandb/sdk/lib/sock_client.py", line 151, in _send_message
    self._sendall_with_error_handle(header + data)
  File "/home/cxccxc/anaconda3/envs/SDXL/lib/python3.10/site-packages/wandb/sdk/lib/sock_client.py", line 130, in _sendall_with_error_handle
    sent = self._sock.send(data)
BrokenPipeError: [Errno 32] Broken pipe
2025-03-28 17:44:33,469 ERROR   MainThread:313412 [redirect.py:_on_write():661] error in stderr callback
Traceback (most recent call last):
  File "/home/cxccxc/anaconda3/envs/SDXL/lib/python3.10/site-packages/wandb/sdk/lib/redirect.py", line 659, in _on_write
    cb(written_data)
  File "/home/cxccxc/anaconda3/envs/SDXL/lib/python3.10/site-packages/wandb/sdk/wandb_run.py", line 2302, in <lambda>
    lambda data: self._console_raw_callback("stderr", data),
  File "/home/cxccxc/anaconda3/envs/SDXL/lib/python3.10/site-packages/wandb/sdk/wandb_run.py", line 401, in wrapper_fn
    return func(self, *args, **kwargs)
  File "/home/cxccxc/anaconda3/envs/SDXL/lib/python3.10/site-packages/wandb/sdk/wandb_run.py", line 1444, in _console_raw_callback
    self._backend.interface.publish_output_raw(name, data)
  File "/home/cxccxc/anaconda3/envs/SDXL/lib/python3.10/site-packages/wandb/sdk/interface/interface.py", line 761, in publish_output_raw
    self._publish_output_raw(o)
  File "/home/cxccxc/anaconda3/envs/SDXL/lib/python3.10/site-packages/wandb/sdk/interface/interface_shared.py", line 38, in _publish_output_raw
    self._publish(rec)
  File "/home/cxccxc/anaconda3/envs/SDXL/lib/python3.10/site-packages/wandb/sdk/interface/interface_sock.py", line 39, in _publish
    self._sock_client.send_record_publish(record)
  File "/home/cxccxc/anaconda3/envs/SDXL/lib/python3.10/site-packages/wandb/sdk/lib/sock_client.py", line 174, in send_record_publish
    self.send_server_request(server_req)
  File "/home/cxccxc/anaconda3/envs/SDXL/lib/python3.10/site-packages/wandb/sdk/lib/sock_client.py", line 154, in send_server_request
    self._send_message(msg)
  File "/home/cxccxc/anaconda3/envs/SDXL/lib/python3.10/site-packages/wandb/sdk/lib/sock_client.py", line 151, in _send_message
    self._sendall_with_error_handle(header + data)
  File "/home/cxccxc/anaconda3/envs/SDXL/lib/python3.10/site-packages/wandb/sdk/lib/sock_client.py", line 130, in _sendall_with_error_handle
    sent = self._sock.send(data)
BrokenPipeError: [Errno 32] Broken pipe
2025-03-28 17:44:33,469 ERROR   MainThread:313412 [redirect.py:_on_write():661] error in stderr callback
Traceback (most recent call last):
  File "/home/cxccxc/anaconda3/envs/SDXL/lib/python3.10/site-packages/wandb/sdk/lib/redirect.py", line 659, in _on_write
    cb(written_data)
  File "/home/cxccxc/anaconda3/envs/SDXL/lib/python3.10/site-packages/wandb/sdk/wandb_run.py", line 2302, in <lambda>
    lambda data: self._console_raw_callback("stderr", data),
  File "/home/cxccxc/anaconda3/envs/SDXL/lib/python3.10/site-packages/wandb/sdk/wandb_run.py", line 401, in wrapper_fn
    return func(self, *args, **kwargs)
  File "/home/cxccxc/anaconda3/envs/SDXL/lib/python3.10/site-packages/wandb/sdk/wandb_run.py", line 1444, in _console_raw_callback
    self._backend.interface.publish_output_raw(name, data)
  File "/home/cxccxc/anaconda3/envs/SDXL/lib/python3.10/site-packages/wandb/sdk/interface/interface.py", line 761, in publish_output_raw
    self._publish_output_raw(o)
  File "/home/cxccxc/anaconda3/envs/SDXL/lib/python3.10/site-packages/wandb/sdk/interface/interface_shared.py", line 38, in _publish_output_raw
    self._publish(rec)
  File "/home/cxccxc/anaconda3/envs/SDXL/lib/python3.10/site-packages/wandb/sdk/interface/interface_sock.py", line 39, in _publish
    self._sock_client.send_record_publish(record)
  File "/home/cxccxc/anaconda3/envs/SDXL/lib/python3.10/site-packages/wandb/sdk/lib/sock_client.py", line 174, in send_record_publish
    self.send_server_request(server_req)
  File "/home/cxccxc/anaconda3/envs/SDXL/lib/python3.10/site-packages/wandb/sdk/lib/sock_client.py", line 154, in send_server_request
    self._send_message(msg)
  File "/home/cxccxc/anaconda3/envs/SDXL/lib/python3.10/site-packages/wandb/sdk/lib/sock_client.py", line 151, in _send_message
    self._sendall_with_error_handle(header + data)
  File "/home/cxccxc/anaconda3/envs/SDXL/lib/python3.10/site-packages/wandb/sdk/lib/sock_client.py", line 130, in _sendall_with_error_handle
    sent = self._sock.send(data)
BrokenPipeError: [Errno 32] Broken pipe
2025-03-28 17:44:33,470 ERROR   MainThread:313412 [redirect.py:_on_write():661] error in stderr callback
Traceback (most recent call last):
  File "/home/cxccxc/anaconda3/envs/SDXL/lib/python3.10/site-packages/wandb/sdk/lib/redirect.py", line 659, in _on_write
    cb(written_data)
  File "/home/cxccxc/anaconda3/envs/SDXL/lib/python3.10/site-packages/wandb/sdk/wandb_run.py", line 2302, in <lambda>
    lambda data: self._console_raw_callback("stderr", data),
  File "/home/cxccxc/anaconda3/envs/SDXL/lib/python3.10/site-packages/wandb/sdk/wandb_run.py", line 401, in wrapper_fn
    return func(self, *args, **kwargs)
  File "/home/cxccxc/anaconda3/envs/SDXL/lib/python3.10/site-packages/wandb/sdk/wandb_run.py", line 1444, in _console_raw_callback
    self._backend.interface.publish_output_raw(name, data)
  File "/home/cxccxc/anaconda3/envs/SDXL/lib/python3.10/site-packages/wandb/sdk/interface/interface.py", line 761, in publish_output_raw
    self._publish_output_raw(o)
  File "/home/cxccxc/anaconda3/envs/SDXL/lib/python3.10/site-packages/wandb/sdk/interface/interface_shared.py", line 38, in _publish_output_raw
    self._publish(rec)
  File "/home/cxccxc/anaconda3/envs/SDXL/lib/python3.10/site-packages/wandb/sdk/interface/interface_sock.py", line 39, in _publish
    self._sock_client.send_record_publish(record)
  File "/home/cxccxc/anaconda3/envs/SDXL/lib/python3.10/site-packages/wandb/sdk/lib/sock_client.py", line 174, in send_record_publish
    self.send_server_request(server_req)
  File "/home/cxccxc/anaconda3/envs/SDXL/lib/python3.10/site-packages/wandb/sdk/lib/sock_client.py", line 154, in send_server_request
    self._send_message(msg)
  File "/home/cxccxc/anaconda3/envs/SDXL/lib/python3.10/site-packages/wandb/sdk/lib/sock_client.py", line 151, in _send_message
    self._sendall_with_error_handle(header + data)
  File "/home/cxccxc/anaconda3/envs/SDXL/lib/python3.10/site-packages/wandb/sdk/lib/sock_client.py", line 130, in _sendall_with_error_handle
    sent = self._sock.send(data)
BrokenPipeError: [Errno 32] Broken pipe
2025-03-28 17:44:33,470 ERROR   MainThread:313412 [redirect.py:_on_write():661] error in stderr callback
Traceback (most recent call last):
  File "/home/cxccxc/anaconda3/envs/SDXL/lib/python3.10/site-packages/wandb/sdk/lib/redirect.py", line 659, in _on_write
    cb(written_data)
  File "/home/cxccxc/anaconda3/envs/SDXL/lib/python3.10/site-packages/wandb/sdk/wandb_run.py", line 2302, in <lambda>
    lambda data: self._console_raw_callback("stderr", data),
  File "/home/cxccxc/anaconda3/envs/SDXL/lib/python3.10/site-packages/wandb/sdk/wandb_run.py", line 401, in wrapper_fn
    return func(self, *args, **kwargs)
  File "/home/cxccxc/anaconda3/envs/SDXL/lib/python3.10/site-packages/wandb/sdk/wandb_run.py", line 1444, in _console_raw_callback
    self._backend.interface.publish_output_raw(name, data)
  File "/home/cxccxc/anaconda3/envs/SDXL/lib/python3.10/site-packages/wandb/sdk/interface/interface.py", line 761, in publish_output_raw
    self._publish_output_raw(o)
  File "/home/cxccxc/anaconda3/envs/SDXL/lib/python3.10/site-packages/wandb/sdk/interface/interface_shared.py", line 38, in _publish_output_raw
    self._publish(rec)
  File "/home/cxccxc/anaconda3/envs/SDXL/lib/python3.10/site-packages/wandb/sdk/interface/interface_sock.py", line 39, in _publish
    self._sock_client.send_record_publish(record)
  File "/home/cxccxc/anaconda3/envs/SDXL/lib/python3.10/site-packages/wandb/sdk/lib/sock_client.py", line 174, in send_record_publish
    self.send_server_request(server_req)
  File "/home/cxccxc/anaconda3/envs/SDXL/lib/python3.10/site-packages/wandb/sdk/lib/sock_client.py", line 154, in send_server_request
    self._send_message(msg)
  File "/home/cxccxc/anaconda3/envs/SDXL/lib/python3.10/site-packages/wandb/sdk/lib/sock_client.py", line 151, in _send_message
    self._sendall_with_error_handle(header + data)
  File "/home/cxccxc/anaconda3/envs/SDXL/lib/python3.10/site-packages/wandb/sdk/lib/sock_client.py", line 130, in _sendall_with_error_handle
    sent = self._sock.send(data)
BrokenPipeError: [Errno 32] Broken pipe
2025-03-28 17:44:33,470 ERROR   MainThread:313412 [redirect.py:_on_write():661] error in stderr callback
Traceback (most recent call last):
  File "/home/cxccxc/anaconda3/envs/SDXL/lib/python3.10/site-packages/wandb/sdk/lib/redirect.py", line 659, in _on_write
    cb(written_data)
  File "/home/cxccxc/anaconda3/envs/SDXL/lib/python3.10/site-packages/wandb/sdk/wandb_run.py", line 2302, in <lambda>
    lambda data: self._console_raw_callback("stderr", data),
  File "/home/cxccxc/anaconda3/envs/SDXL/lib/python3.10/site-packages/wandb/sdk/wandb_run.py", line 401, in wrapper_fn
    return func(self, *args, **kwargs)
  File "/home/cxccxc/anaconda3/envs/SDXL/lib/python3.10/site-packages/wandb/sdk/wandb_run.py", line 1444, in _console_raw_callback
    self._backend.interface.publish_output_raw(name, data)
  File "/home/cxccxc/anaconda3/envs/SDXL/lib/python3.10/site-packages/wandb/sdk/interface/interface.py", line 761, in publish_output_raw
    self._publish_output_raw(o)
  File "/home/cxccxc/anaconda3/envs/SDXL/lib/python3.10/site-packages/wandb/sdk/interface/interface_shared.py", line 38, in _publish_output_raw
    self._publish(rec)
  File "/home/cxccxc/anaconda3/envs/SDXL/lib/python3.10/site-packages/wandb/sdk/interface/interface_sock.py", line 39, in _publish
    self._sock_client.send_record_publish(record)
  File "/home/cxccxc/anaconda3/envs/SDXL/lib/python3.10/site-packages/wandb/sdk/lib/sock_client.py", line 174, in send_record_publish
    self.send_server_request(server_req)
  File "/home/cxccxc/anaconda3/envs/SDXL/lib/python3.10/site-packages/wandb/sdk/lib/sock_client.py", line 154, in send_server_request
    self._send_message(msg)
  File "/home/cxccxc/anaconda3/envs/SDXL/lib/python3.10/site-packages/wandb/sdk/lib/sock_client.py", line 151, in _send_message
    self._sendall_with_error_handle(header + data)
  File "/home/cxccxc/anaconda3/envs/SDXL/lib/python3.10/site-packages/wandb/sdk/lib/sock_client.py", line 130, in _sendall_with_error_handle
    sent = self._sock.send(data)
BrokenPipeError: [Errno 32] Broken pipe
2025-03-28 17:44:33,470 ERROR   MainThread:313412 [redirect.py:_on_write():661] error in stderr callback
Traceback (most recent call last):
  File "/home/cxccxc/anaconda3/envs/SDXL/lib/python3.10/site-packages/wandb/sdk/lib/redirect.py", line 659, in _on_write
    cb(written_data)
  File "/home/cxccxc/anaconda3/envs/SDXL/lib/python3.10/site-packages/wandb/sdk/wandb_run.py", line 2302, in <lambda>
    lambda data: self._console_raw_callback("stderr", data),
  File "/home/cxccxc/anaconda3/envs/SDXL/lib/python3.10/site-packages/wandb/sdk/wandb_run.py", line 401, in wrapper_fn
    return func(self, *args, **kwargs)
  File "/home/cxccxc/anaconda3/envs/SDXL/lib/python3.10/site-packages/wandb/sdk/wandb_run.py", line 1444, in _console_raw_callback
    self._backend.interface.publish_output_raw(name, data)
  File "/home/cxccxc/anaconda3/envs/SDXL/lib/python3.10/site-packages/wandb/sdk/interface/interface.py", line 761, in publish_output_raw
    self._publish_output_raw(o)
  File "/home/cxccxc/anaconda3/envs/SDXL/lib/python3.10/site-packages/wandb/sdk/interface/interface_shared.py", line 38, in _publish_output_raw
    self._publish(rec)
  File "/home/cxccxc/anaconda3/envs/SDXL/lib/python3.10/site-packages/wandb/sdk/interface/interface_sock.py", line 39, in _publish
    self._sock_client.send_record_publish(record)
  File "/home/cxccxc/anaconda3/envs/SDXL/lib/python3.10/site-packages/wandb/sdk/lib/sock_client.py", line 174, in send_record_publish
    self.send_server_request(server_req)
  File "/home/cxccxc/anaconda3/envs/SDXL/lib/python3.10/site-packages/wandb/sdk/lib/sock_client.py", line 154, in send_server_request
    self._send_message(msg)
  File "/home/cxccxc/anaconda3/envs/SDXL/lib/python3.10/site-packages/wandb/sdk/lib/sock_client.py", line 151, in _send_message
    self._sendall_with_error_handle(header + data)
  File "/home/cxccxc/anaconda3/envs/SDXL/lib/python3.10/site-packages/wandb/sdk/lib/sock_client.py", line 130, in _sendall_with_error_handle
    sent = self._sock.send(data)
BrokenPipeError: [Errno 32] Broken pipe
2025-03-28 17:44:33,471 ERROR   MainThread:313412 [redirect.py:_on_write():661] error in stderr callback
Traceback (most recent call last):
  File "/home/cxccxc/anaconda3/envs/SDXL/lib/python3.10/site-packages/wandb/sdk/lib/redirect.py", line 659, in _on_write
    cb(written_data)
  File "/home/cxccxc/anaconda3/envs/SDXL/lib/python3.10/site-packages/wandb/sdk/wandb_run.py", line 2302, in <lambda>
    lambda data: self._console_raw_callback("stderr", data),
  File "/home/cxccxc/anaconda3/envs/SDXL/lib/python3.10/site-packages/wandb/sdk/wandb_run.py", line 401, in wrapper_fn
    return func(self, *args, **kwargs)
  File "/home/cxccxc/anaconda3/envs/SDXL/lib/python3.10/site-packages/wandb/sdk/wandb_run.py", line 1444, in _console_raw_callback
    self._backend.interface.publish_output_raw(name, data)
  File "/home/cxccxc/anaconda3/envs/SDXL/lib/python3.10/site-packages/wandb/sdk/interface/interface.py", line 761, in publish_output_raw
    self._publish_output_raw(o)
  File "/home/cxccxc/anaconda3/envs/SDXL/lib/python3.10/site-packages/wandb/sdk/interface/interface_shared.py", line 38, in _publish_output_raw
    self._publish(rec)
  File "/home/cxccxc/anaconda3/envs/SDXL/lib/python3.10/site-packages/wandb/sdk/interface/interface_sock.py", line 39, in _publish
    self._sock_client.send_record_publish(record)
  File "/home/cxccxc/anaconda3/envs/SDXL/lib/python3.10/site-packages/wandb/sdk/lib/sock_client.py", line 174, in send_record_publish
    self.send_server_request(server_req)
  File "/home/cxccxc/anaconda3/envs/SDXL/lib/python3.10/site-packages/wandb/sdk/lib/sock_client.py", line 154, in send_server_request
    self._send_message(msg)
  File "/home/cxccxc/anaconda3/envs/SDXL/lib/python3.10/site-packages/wandb/sdk/lib/sock_client.py", line 151, in _send_message
    self._sendall_with_error_handle(header + data)
  File "/home/cxccxc/anaconda3/envs/SDXL/lib/python3.10/site-packages/wandb/sdk/lib/sock_client.py", line 130, in _sendall_with_error_handle
    sent = self._sock.send(data)
BrokenPipeError: [Errno 32] Broken pipe
2025-03-28 17:44:33,471 ERROR   MainThread:313412 [redirect.py:_on_write():661] error in stderr callback
Traceback (most recent call last):
  File "/home/cxccxc/anaconda3/envs/SDXL/lib/python3.10/site-packages/wandb/sdk/lib/redirect.py", line 659, in _on_write
    cb(written_data)
  File "/home/cxccxc/anaconda3/envs/SDXL/lib/python3.10/site-packages/wandb/sdk/wandb_run.py", line 2302, in <lambda>
    lambda data: self._console_raw_callback("stderr", data),
  File "/home/cxccxc/anaconda3/envs/SDXL/lib/python3.10/site-packages/wandb/sdk/wandb_run.py", line 401, in wrapper_fn
    return func(self, *args, **kwargs)
  File "/home/cxccxc/anaconda3/envs/SDXL/lib/python3.10/site-packages/wandb/sdk/wandb_run.py", line 1444, in _console_raw_callback
    self._backend.interface.publish_output_raw(name, data)
  File "/home/cxccxc/anaconda3/envs/SDXL/lib/python3.10/site-packages/wandb/sdk/interface/interface.py", line 761, in publish_output_raw
    self._publish_output_raw(o)
  File "/home/cxccxc/anaconda3/envs/SDXL/lib/python3.10/site-packages/wandb/sdk/interface/interface_shared.py", line 38, in _publish_output_raw
    self._publish(rec)
  File "/home/cxccxc/anaconda3/envs/SDXL/lib/python3.10/site-packages/wandb/sdk/interface/interface_sock.py", line 39, in _publish
    self._sock_client.send_record_publish(record)
  File "/home/cxccxc/anaconda3/envs/SDXL/lib/python3.10/site-packages/wandb/sdk/lib/sock_client.py", line 174, in send_record_publish
    self.send_server_request(server_req)
  File "/home/cxccxc/anaconda3/envs/SDXL/lib/python3.10/site-packages/wandb/sdk/lib/sock_client.py", line 154, in send_server_request
    self._send_message(msg)
  File "/home/cxccxc/anaconda3/envs/SDXL/lib/python3.10/site-packages/wandb/sdk/lib/sock_client.py", line 151, in _send_message
    self._sendall_with_error_handle(header + data)
  File "/home/cxccxc/anaconda3/envs/SDXL/lib/python3.10/site-packages/wandb/sdk/lib/sock_client.py", line 130, in _sendall_with_error_handle
    sent = self._sock.send(data)
BrokenPipeError: [Errno 32] Broken pipe
